2019-07-16 09:46:59,619 [ERROR]  Unable to start server
Traceback (most recent call last):
  File "uvloop/loop.pyx", line 1112, in uvloop.loop.Loop._create_server
  File "uvloop/handles/streamserver.pyx", line 58, in uvloop.loop.UVStreamServer.listen
  File "uvloop/handles/streamserver.pyx", line 95, in uvloop.loop.UVStreamServer._fatal_error
OSError: [Errno 98] Address already in use

During handling of the above exception, another exception occurred:

Traceback (most recent call last):
  File "/home/abwao/.local/lib/python3.6/site-packages/sanic/server.py", line 745, in serve
    http_server = loop.run_until_complete(server_coroutine)
  File "uvloop/loop.pyx", line 1451, in uvloop.loop.Loop.run_until_complete
  File "uvloop/loop.pyx", line 1684, in create_server
  File "uvloop/loop.pyx", line 1116, in uvloop.loop.Loop._create_server
OSError: [Errno 98] error while attempting to bind on address ('0.0.0.0', 5005): address already in use
2019-07-16 09:48:21,088 [ERROR]  Unable to start server
Traceback (most recent call last):
  File "uvloop/loop.pyx", line 1112, in uvloop.loop.Loop._create_server
  File "uvloop/handles/streamserver.pyx", line 58, in uvloop.loop.UVStreamServer.listen
  File "uvloop/handles/streamserver.pyx", line 95, in uvloop.loop.UVStreamServer._fatal_error
OSError: [Errno 98] Address already in use

During handling of the above exception, another exception occurred:

Traceback (most recent call last):
  File "/home/abwao/.local/lib/python3.6/site-packages/sanic/server.py", line 745, in serve
    http_server = loop.run_until_complete(server_coroutine)
  File "uvloop/loop.pyx", line 1451, in uvloop.loop.Loop.run_until_complete
  File "uvloop/loop.pyx", line 1684, in create_server
  File "uvloop/loop.pyx", line 1116, in uvloop.loop.Loop._create_server
OSError: [Errno 98] error while attempting to bind on address ('0.0.0.0', 5005): address already in use
2019-07-17 15:31:17,167 [ERROR]  Unable to start server
Traceback (most recent call last):
  File "uvloop/loop.pyx", line 1112, in uvloop.loop.Loop._create_server
  File "uvloop/handles/streamserver.pyx", line 58, in uvloop.loop.UVStreamServer.listen
  File "uvloop/handles/streamserver.pyx", line 95, in uvloop.loop.UVStreamServer._fatal_error
OSError: [Errno 98] Address already in use

During handling of the above exception, another exception occurred:

Traceback (most recent call last):
  File "/home/abwao/.local/lib/python3.6/site-packages/sanic/server.py", line 745, in serve
    http_server = loop.run_until_complete(server_coroutine)
  File "uvloop/loop.pyx", line 1451, in uvloop.loop.Loop.run_until_complete
  File "uvloop/loop.pyx", line 1684, in create_server
  File "uvloop/loop.pyx", line 1116, in uvloop.loop.Loop._create_server
OSError: [Errno 98] error while attempting to bind on address ('0.0.0.0', 5005): address already in use
2019-07-18 16:41:00,821 [ERROR]  Exception occurred while handling uri: 'http://5c785c74.ngrok.io/'
Traceback (most recent call last):
  File "/home/abwao/.local/lib/python3.6/site-packages/sanic/app.py", line 893, in handle_request
    handler, args, kwargs, uri = self.router.get(request)
  File "/home/abwao/.local/lib/python3.6/site-packages/sanic/router.py", line 407, in get
    return self._get(request.path, request.method, "")
  File "/home/abwao/.local/lib/python3.6/site-packages/sanic/router.py", line 469, in _get
    raise NotFound("Requested URL {} not found".format(url))
sanic.exceptions.NotFound: Requested URL / not found
2019-07-18 16:41:03,257 [ERROR]  Exception occurred while handling uri: 'http://5c785c74.ngrok.io/'
Traceback (most recent call last):
  File "/home/abwao/.local/lib/python3.6/site-packages/sanic/app.py", line 893, in handle_request
    handler, args, kwargs, uri = self.router.get(request)
  File "/home/abwao/.local/lib/python3.6/site-packages/sanic/router.py", line 407, in get
    return self._get(request.path, request.method, "")
  File "/home/abwao/.local/lib/python3.6/site-packages/sanic/router.py", line 469, in _get
    raise NotFound("Requested URL {} not found".format(url))
sanic.exceptions.NotFound: Requested URL / not found
2019-07-18 16:42:08,260 [ERROR]  Exception occurred while handling uri: 'http://39a222b1.ngrok.io/'
Traceback (most recent call last):
  File "/home/abwao/.local/lib/python3.6/site-packages/sanic/app.py", line 893, in handle_request
    handler, args, kwargs, uri = self.router.get(request)
  File "/home/abwao/.local/lib/python3.6/site-packages/sanic/router.py", line 407, in get
    return self._get(request.path, request.method, "")
  File "/home/abwao/.local/lib/python3.6/site-packages/sanic/router.py", line 469, in _get
    raise NotFound("Requested URL {} not found".format(url))
sanic.exceptions.NotFound: Requested URL / not found
2019-07-18 16:42:21,077 [ERROR]  Exception occurred while handling uri: 'http://39a222b1.ngrok.io/'
Traceback (most recent call last):
  File "/home/abwao/.local/lib/python3.6/site-packages/sanic/app.py", line 893, in handle_request
    handler, args, kwargs, uri = self.router.get(request)
  File "/home/abwao/.local/lib/python3.6/site-packages/sanic/router.py", line 407, in get
    return self._get(request.path, request.method, "")
  File "/home/abwao/.local/lib/python3.6/site-packages/sanic/router.py", line 469, in _get
    raise NotFound("Requested URL {} not found".format(url))
sanic.exceptions.NotFound: Requested URL / not found
2019-07-18 16:42:30,859 [ERROR]  Exception occurred while handling uri: 'http://39a222b1.ngrok.io/webhook'
Traceback (most recent call last):
  File "/home/abwao/.local/lib/python3.6/site-packages/sanic/app.py", line 893, in handle_request
    handler, args, kwargs, uri = self.router.get(request)
  File "/home/abwao/.local/lib/python3.6/site-packages/sanic/router.py", line 407, in get
    return self._get(request.path, request.method, "")
  File "/home/abwao/.local/lib/python3.6/site-packages/sanic/router.py", line 469, in _get
    raise NotFound("Requested URL {} not found".format(url))
sanic.exceptions.NotFound: Requested URL /webhook not found
2019-07-18 16:43:46,507 [ERROR]  Exception occurred while handling uri: 'http://39a222b1.ngrok.io/'
Traceback (most recent call last):
  File "/home/abwao/.local/lib/python3.6/site-packages/sanic/app.py", line 893, in handle_request
    handler, args, kwargs, uri = self.router.get(request)
  File "/home/abwao/.local/lib/python3.6/site-packages/sanic/router.py", line 407, in get
    return self._get(request.path, request.method, "")
  File "/home/abwao/.local/lib/python3.6/site-packages/sanic/router.py", line 469, in _get
    raise NotFound("Requested URL {} not found".format(url))
sanic.exceptions.NotFound: Requested URL / not found
2019-07-18 16:44:10,754 [ERROR]  Exception occurred while handling uri: 'http://39a222b1.ngrok.io/'
Traceback (most recent call last):
  File "/home/abwao/.local/lib/python3.6/site-packages/sanic/app.py", line 893, in handle_request
    handler, args, kwargs, uri = self.router.get(request)
  File "/home/abwao/.local/lib/python3.6/site-packages/sanic/router.py", line 407, in get
    return self._get(request.path, request.method, "")
  File "/home/abwao/.local/lib/python3.6/site-packages/sanic/router.py", line 469, in _get
    raise NotFound("Requested URL {} not found".format(url))
sanic.exceptions.NotFound: Requested URL / not found
2019-07-18 16:45:01,493 [ERROR]  Exception occurred while handling uri: 'http://4dccc294.ngrok.io/webhook'
Traceback (most recent call last):
  File "/home/abwao/.local/lib/python3.6/site-packages/sanic/app.py", line 893, in handle_request
    handler, args, kwargs, uri = self.router.get(request)
  File "/home/abwao/.local/lib/python3.6/site-packages/sanic/router.py", line 407, in get
    return self._get(request.path, request.method, "")
  File "/home/abwao/.local/lib/python3.6/site-packages/sanic/router.py", line 469, in _get
    raise NotFound("Requested URL {} not found".format(url))
sanic.exceptions.NotFound: Requested URL /webhook not found
2019-07-18 17:44:54,357 [ERROR]  Exception occurred while handling uri: 'http://855cc9d3.ngrok.io/webhooks/'
Traceback (most recent call last):
  File "/home/abwao/.local/lib/python3.6/site-packages/sanic/app.py", line 893, in handle_request
    handler, args, kwargs, uri = self.router.get(request)
  File "/home/abwao/.local/lib/python3.6/site-packages/sanic/router.py", line 407, in get
    return self._get(request.path, request.method, "")
  File "/home/abwao/.local/lib/python3.6/site-packages/sanic/router.py", line 469, in _get
    raise NotFound("Requested URL {} not found".format(url))
sanic.exceptions.NotFound: Requested URL /webhooks/ not found
2019-07-18 17:44:56,610 [ERROR]  Exception occurred while handling uri: 'http://855cc9d3.ngrok.io/webhooks/'
Traceback (most recent call last):
  File "/home/abwao/.local/lib/python3.6/site-packages/sanic/app.py", line 893, in handle_request
    handler, args, kwargs, uri = self.router.get(request)
  File "/home/abwao/.local/lib/python3.6/site-packages/sanic/router.py", line 407, in get
    return self._get(request.path, request.method, "")
  File "/home/abwao/.local/lib/python3.6/site-packages/sanic/router.py", line 469, in _get
    raise NotFound("Requested URL {} not found".format(url))
sanic.exceptions.NotFound: Requested URL /webhooks/ not found
2019-07-22 09:28:21,994 [ERROR]  Exception occurred while handling uri: 'http://localhost:5005/socket.io/?EIO=3&transport=polling&t=MmONUD8'
Traceback (most recent call last):
  File "/home/abwao/.local/lib/python3.6/site-packages/sanic/app.py", line 893, in handle_request
    handler, args, kwargs, uri = self.router.get(request)
  File "/home/abwao/.local/lib/python3.6/site-packages/sanic/router.py", line 407, in get
    return self._get(request.path, request.method, "")
  File "/home/abwao/.local/lib/python3.6/site-packages/sanic/router.py", line 469, in _get
    raise NotFound("Requested URL {} not found".format(url))
sanic.exceptions.NotFound: Requested URL /socket.io/ not found
2019-07-22 09:28:27,966 [ERROR]  Exception occurred while handling uri: 'http://localhost:5005/socket.io/?EIO=3&transport=polling&t=MmONVgv'
Traceback (most recent call last):
  File "/home/abwao/.local/lib/python3.6/site-packages/sanic/app.py", line 893, in handle_request
    handler, args, kwargs, uri = self.router.get(request)
  File "/home/abwao/.local/lib/python3.6/site-packages/sanic/router.py", line 407, in get
    return self._get(request.path, request.method, "")
  File "/home/abwao/.local/lib/python3.6/site-packages/sanic/router.py", line 469, in _get
    raise NotFound("Requested URL {} not found".format(url))
sanic.exceptions.NotFound: Requested URL /socket.io/ not found
2019-07-22 09:28:33,969 [ERROR]  Exception occurred while handling uri: 'http://localhost:5005/socket.io/?EIO=3&transport=polling&t=MmONX8f'
Traceback (most recent call last):
  File "/home/abwao/.local/lib/python3.6/site-packages/sanic/app.py", line 893, in handle_request
    handler, args, kwargs, uri = self.router.get(request)
  File "/home/abwao/.local/lib/python3.6/site-packages/sanic/router.py", line 407, in get
    return self._get(request.path, request.method, "")
  File "/home/abwao/.local/lib/python3.6/site-packages/sanic/router.py", line 469, in _get
    raise NotFound("Requested URL {} not found".format(url))
sanic.exceptions.NotFound: Requested URL /socket.io/ not found
2019-07-22 09:28:39,966 [ERROR]  Exception occurred while handling uri: 'http://localhost:5005/socket.io/?EIO=3&transport=polling&t=MmONYcQ'
Traceback (most recent call last):
  File "/home/abwao/.local/lib/python3.6/site-packages/sanic/app.py", line 893, in handle_request
    handler, args, kwargs, uri = self.router.get(request)
  File "/home/abwao/.local/lib/python3.6/site-packages/sanic/router.py", line 407, in get
    return self._get(request.path, request.method, "")
  File "/home/abwao/.local/lib/python3.6/site-packages/sanic/router.py", line 469, in _get
    raise NotFound("Requested URL {} not found".format(url))
sanic.exceptions.NotFound: Requested URL /socket.io/ not found
2019-07-22 09:28:45,966 [ERROR]  Exception occurred while handling uri: 'http://localhost:5005/socket.io/?EIO=3&transport=polling&t=MmONa49'
Traceback (most recent call last):
  File "/home/abwao/.local/lib/python3.6/site-packages/sanic/app.py", line 893, in handle_request
    handler, args, kwargs, uri = self.router.get(request)
  File "/home/abwao/.local/lib/python3.6/site-packages/sanic/router.py", line 407, in get
    return self._get(request.path, request.method, "")
  File "/home/abwao/.local/lib/python3.6/site-packages/sanic/router.py", line 469, in _get
    raise NotFound("Requested URL {} not found".format(url))
sanic.exceptions.NotFound: Requested URL /socket.io/ not found
2019-07-22 09:28:51,968 [ERROR]  Exception occurred while handling uri: 'http://localhost:5005/socket.io/?EIO=3&transport=polling&t=MmONbXv'
Traceback (most recent call last):
  File "/home/abwao/.local/lib/python3.6/site-packages/sanic/app.py", line 893, in handle_request
    handler, args, kwargs, uri = self.router.get(request)
  File "/home/abwao/.local/lib/python3.6/site-packages/sanic/router.py", line 407, in get
    return self._get(request.path, request.method, "")
  File "/home/abwao/.local/lib/python3.6/site-packages/sanic/router.py", line 469, in _get
    raise NotFound("Requested URL {} not found".format(url))
sanic.exceptions.NotFound: Requested URL /socket.io/ not found
2019-07-22 09:28:57,967 [ERROR]  Exception occurred while handling uri: 'http://localhost:5005/socket.io/?EIO=3&transport=polling&t=MmONc_e'
Traceback (most recent call last):
  File "/home/abwao/.local/lib/python3.6/site-packages/sanic/app.py", line 893, in handle_request
    handler, args, kwargs, uri = self.router.get(request)
  File "/home/abwao/.local/lib/python3.6/site-packages/sanic/router.py", line 407, in get
    return self._get(request.path, request.method, "")
  File "/home/abwao/.local/lib/python3.6/site-packages/sanic/router.py", line 469, in _get
    raise NotFound("Requested URL {} not found".format(url))
sanic.exceptions.NotFound: Requested URL /socket.io/ not found
2019-07-22 09:29:03,972 [ERROR]  Exception occurred while handling uri: 'http://localhost:5005/socket.io/?EIO=3&transport=polling&t=MmONeTO'
Traceback (most recent call last):
  File "/home/abwao/.local/lib/python3.6/site-packages/sanic/app.py", line 893, in handle_request
    handler, args, kwargs, uri = self.router.get(request)
  File "/home/abwao/.local/lib/python3.6/site-packages/sanic/router.py", line 407, in get
    return self._get(request.path, request.method, "")
  File "/home/abwao/.local/lib/python3.6/site-packages/sanic/router.py", line 469, in _get
    raise NotFound("Requested URL {} not found".format(url))
sanic.exceptions.NotFound: Requested URL /socket.io/ not found
2019-07-22 09:29:09,968 [ERROR]  Exception occurred while handling uri: 'http://localhost:5005/socket.io/?EIO=3&transport=polling&t=MmONfx9'
Traceback (most recent call last):
  File "/home/abwao/.local/lib/python3.6/site-packages/sanic/app.py", line 893, in handle_request
    handler, args, kwargs, uri = self.router.get(request)
  File "/home/abwao/.local/lib/python3.6/site-packages/sanic/router.py", line 407, in get
    return self._get(request.path, request.method, "")
  File "/home/abwao/.local/lib/python3.6/site-packages/sanic/router.py", line 469, in _get
    raise NotFound("Requested URL {} not found".format(url))
sanic.exceptions.NotFound: Requested URL /socket.io/ not found
2019-07-22 09:29:15,970 [ERROR]  Exception occurred while handling uri: 'http://localhost:5005/socket.io/?EIO=3&transport=polling&t=MmONhOv'
Traceback (most recent call last):
  File "/home/abwao/.local/lib/python3.6/site-packages/sanic/app.py", line 893, in handle_request
    handler, args, kwargs, uri = self.router.get(request)
  File "/home/abwao/.local/lib/python3.6/site-packages/sanic/router.py", line 407, in get
    return self._get(request.path, request.method, "")
  File "/home/abwao/.local/lib/python3.6/site-packages/sanic/router.py", line 469, in _get
    raise NotFound("Requested URL {} not found".format(url))
sanic.exceptions.NotFound: Requested URL /socket.io/ not found
2019-07-22 09:29:21,965 [ERROR]  Exception occurred while handling uri: 'http://localhost:5005/socket.io/?EIO=3&transport=polling&t=MmONisf'
Traceback (most recent call last):
  File "/home/abwao/.local/lib/python3.6/site-packages/sanic/app.py", line 893, in handle_request
    handler, args, kwargs, uri = self.router.get(request)
  File "/home/abwao/.local/lib/python3.6/site-packages/sanic/router.py", line 407, in get
    return self._get(request.path, request.method, "")
  File "/home/abwao/.local/lib/python3.6/site-packages/sanic/router.py", line 469, in _get
    raise NotFound("Requested URL {} not found".format(url))
sanic.exceptions.NotFound: Requested URL /socket.io/ not found
2019-07-22 09:30:02,527 [ERROR]  Exception occurred in one of response middleware handlers
Traceback (most recent call last):
  File "/home/abwao/.local/lib/python3.6/site-packages/sanic/app.py", line 958, in handle_request
    request, response
  File "/home/abwao/.local/lib/python3.6/site-packages/spf/framework.py", line 543, in _run_response_middleware
    _response = await _response
  File "/home/abwao/.local/lib/python3.6/site-packages/sanic_cors/extension.py", line 266, in unapplied_cors_response_middleware
    set_cors_headers(req, resp, context, res_options)
  File "/home/abwao/.local/lib/python3.6/site-packages/sanic_cors/core.py", line 248, in set_cors_headers
    if resp.headers is None:
AttributeError: 'list' object has no attribute 'headers'
2019-07-22 10:20:38,216 [ERROR]  Exception occurred in one of response middleware handlers
Traceback (most recent call last):
  File "/home/abwao/.local/lib/python3.6/site-packages/sanic/app.py", line 958, in handle_request
    request, response
  File "/home/abwao/.local/lib/python3.6/site-packages/spf/framework.py", line 543, in _run_response_middleware
    _response = await _response
  File "/home/abwao/.local/lib/python3.6/site-packages/sanic_cors/extension.py", line 266, in unapplied_cors_response_middleware
    set_cors_headers(req, resp, context, res_options)
  File "/home/abwao/.local/lib/python3.6/site-packages/sanic_cors/core.py", line 248, in set_cors_headers
    if resp.headers is None:
AttributeError: 'list' object has no attribute 'headers'
2019-07-22 10:22:04,413 [ERROR]  Exception occurred while handling uri: 'http://localhost:5005/socket.io/?EIO=3&transport=polling&t=MmOZYIE&sid=4824f2d0084a49fba207e8d5c831fe66'
NoneType: None
2019-07-22 10:22:04,487 [ERROR]  Exception occurred while handling uri: 'ws://localhost:5005/socket.io/?EIO=3&transport=websocket&sid=4824f2d0084a49fba207e8d5c831fe66'
Traceback (most recent call last):
  File "/home/abwao/.local/lib/python3.6/site-packages/sanic/app.py", line 917, in handle_request
    response = await response
  File "/home/abwao/.local/lib/python3.6/site-packages/engineio/asyncio_server.py", line 220, in handle_request
    packets = await socket.handle_get_request(environ)
  File "/home/abwao/.local/lib/python3.6/site-packages/engineio/asyncio_socket.py", line 89, in handle_get_request
    return await getattr(self, '_upgrade_' + transport)(environ)
  File "/home/abwao/.local/lib/python3.6/site-packages/engineio/asyncio_socket.py", line 128, in _upgrade_websocket
    return await ws(environ)
  File "/home/abwao/.local/lib/python3.6/site-packages/engineio/async_drivers/sanic.py", line 122, in __call__
    await self.handler(self)
  File "/home/abwao/.local/lib/python3.6/site-packages/engineio/asyncio_socket.py", line 152, in _websocket_handler
    pkt = await ws.wait()
  File "/home/abwao/.local/lib/python3.6/site-packages/engineio/async_drivers/sanic.py", line 131, in wait
    data = await self._sock.recv()
  File "/home/abwao/.local/lib/python3.6/site-packages/websockets/protocol.py", line 350, in recv
    yield from self.ensure_open()
  File "/home/abwao/.local/lib/python3.6/site-packages/websockets/protocol.py", line 512, in ensure_open
    self.close_code, self.close_reason) from self.transfer_data_exc
websockets.exceptions.ConnectionClosed: WebSocket connection is closed: code = 1005 (no status code [internal]), no reason
2019-07-22 10:23:34,731 [ERROR]  Exception occurred in one of response middleware handlers
Traceback (most recent call last):
  File "/home/abwao/.local/lib/python3.6/site-packages/sanic/app.py", line 958, in handle_request
    request, response
  File "/home/abwao/.local/lib/python3.6/site-packages/spf/framework.py", line 543, in _run_response_middleware
    _response = await _response
  File "/home/abwao/.local/lib/python3.6/site-packages/sanic_cors/extension.py", line 266, in unapplied_cors_response_middleware
    set_cors_headers(req, resp, context, res_options)
  File "/home/abwao/.local/lib/python3.6/site-packages/sanic_cors/core.py", line 248, in set_cors_headers
    if resp.headers is None:
AttributeError: 'list' object has no attribute 'headers'
2019-07-22 10:25:03,370 [ERROR]  Exception occurred in one of response middleware handlers
Traceback (most recent call last):
  File "/home/abwao/.local/lib/python3.6/site-packages/sanic/app.py", line 958, in handle_request
    request, response
  File "/home/abwao/.local/lib/python3.6/site-packages/spf/framework.py", line 543, in _run_response_middleware
    _response = await _response
  File "/home/abwao/.local/lib/python3.6/site-packages/sanic_cors/extension.py", line 266, in unapplied_cors_response_middleware
    set_cors_headers(req, resp, context, res_options)
  File "/home/abwao/.local/lib/python3.6/site-packages/sanic_cors/core.py", line 248, in set_cors_headers
    if resp.headers is None:
AttributeError: 'list' object has no attribute 'headers'
2019-07-22 10:37:48,707 [ERROR]  Exception occurred in one of response middleware handlers
Traceback (most recent call last):
  File "/home/abwao/.local/lib/python3.6/site-packages/sanic/app.py", line 958, in handle_request
    request, response
  File "/home/abwao/.local/lib/python3.6/site-packages/spf/framework.py", line 543, in _run_response_middleware
    _response = await _response
  File "/home/abwao/.local/lib/python3.6/site-packages/sanic_cors/extension.py", line 266, in unapplied_cors_response_middleware
    set_cors_headers(req, resp, context, res_options)
  File "/home/abwao/.local/lib/python3.6/site-packages/sanic_cors/core.py", line 248, in set_cors_headers
    if resp.headers is None:
AttributeError: 'list' object has no attribute 'headers'
2019-07-22 10:40:06,776 [ERROR]  Exception occurred in one of response middleware handlers
Traceback (most recent call last):
  File "/home/abwao/.local/lib/python3.6/site-packages/sanic/app.py", line 958, in handle_request
    request, response
  File "/home/abwao/.local/lib/python3.6/site-packages/spf/framework.py", line 543, in _run_response_middleware
    _response = await _response
  File "/home/abwao/.local/lib/python3.6/site-packages/sanic_cors/extension.py", line 266, in unapplied_cors_response_middleware
    set_cors_headers(req, resp, context, res_options)
  File "/home/abwao/.local/lib/python3.6/site-packages/sanic_cors/core.py", line 248, in set_cors_headers
    if resp.headers is None:
AttributeError: 'list' object has no attribute 'headers'
2019-07-22 10:48:01,340 [ERROR]  Exception occurred in one of response middleware handlers
Traceback (most recent call last):
  File "/home/abwao/.local/lib/python3.6/site-packages/sanic/app.py", line 958, in handle_request
    request, response
  File "/home/abwao/.local/lib/python3.6/site-packages/spf/framework.py", line 543, in _run_response_middleware
    _response = await _response
  File "/home/abwao/.local/lib/python3.6/site-packages/sanic_cors/extension.py", line 266, in unapplied_cors_response_middleware
    set_cors_headers(req, resp, context, res_options)
  File "/home/abwao/.local/lib/python3.6/site-packages/sanic_cors/core.py", line 248, in set_cors_headers
    if resp.headers is None:
AttributeError: 'list' object has no attribute 'headers'
2019-07-22 10:50:16,831 [ERROR]  Exception occurred in one of response middleware handlers
Traceback (most recent call last):
  File "/home/abwao/.local/lib/python3.6/site-packages/sanic/app.py", line 958, in handle_request
    request, response
  File "/home/abwao/.local/lib/python3.6/site-packages/spf/framework.py", line 543, in _run_response_middleware
    _response = await _response
  File "/home/abwao/.local/lib/python3.6/site-packages/sanic_cors/extension.py", line 266, in unapplied_cors_response_middleware
    set_cors_headers(req, resp, context, res_options)
  File "/home/abwao/.local/lib/python3.6/site-packages/sanic_cors/core.py", line 248, in set_cors_headers
    if resp.headers is None:
AttributeError: 'list' object has no attribute 'headers'
2019-07-22 10:50:28,257 [ERROR]  Exception occurred in one of response middleware handlers
Traceback (most recent call last):
  File "/home/abwao/.local/lib/python3.6/site-packages/sanic/app.py", line 958, in handle_request
    request, response
  File "/home/abwao/.local/lib/python3.6/site-packages/spf/framework.py", line 543, in _run_response_middleware
    _response = await _response
  File "/home/abwao/.local/lib/python3.6/site-packages/sanic_cors/extension.py", line 266, in unapplied_cors_response_middleware
    set_cors_headers(req, resp, context, res_options)
  File "/home/abwao/.local/lib/python3.6/site-packages/sanic_cors/core.py", line 248, in set_cors_headers
    if resp.headers is None:
AttributeError: 'list' object has no attribute 'headers'
2019-07-22 10:50:33,086 [ERROR]  Exception occurred in one of response middleware handlers
Traceback (most recent call last):
  File "/home/abwao/.local/lib/python3.6/site-packages/sanic/app.py", line 958, in handle_request
    request, response
  File "/home/abwao/.local/lib/python3.6/site-packages/spf/framework.py", line 543, in _run_response_middleware
    _response = await _response
  File "/home/abwao/.local/lib/python3.6/site-packages/sanic_cors/extension.py", line 266, in unapplied_cors_response_middleware
    set_cors_headers(req, resp, context, res_options)
  File "/home/abwao/.local/lib/python3.6/site-packages/sanic_cors/core.py", line 248, in set_cors_headers
    if resp.headers is None:
AttributeError: 'list' object has no attribute 'headers'
2019-07-22 10:50:34,103 [ERROR]  Exception occurred in one of response middleware handlers
Traceback (most recent call last):
  File "/home/abwao/.local/lib/python3.6/site-packages/sanic/app.py", line 958, in handle_request
    request, response
  File "/home/abwao/.local/lib/python3.6/site-packages/spf/framework.py", line 543, in _run_response_middleware
    _response = await _response
  File "/home/abwao/.local/lib/python3.6/site-packages/sanic_cors/extension.py", line 266, in unapplied_cors_response_middleware
    set_cors_headers(req, resp, context, res_options)
  File "/home/abwao/.local/lib/python3.6/site-packages/sanic_cors/core.py", line 248, in set_cors_headers
    if resp.headers is None:
AttributeError: 'list' object has no attribute 'headers'
2019-07-22 10:56:16,354 [ERROR]  Exception occurred in one of response middleware handlers
Traceback (most recent call last):
  File "/home/abwao/.local/lib/python3.6/site-packages/sanic/app.py", line 958, in handle_request
    request, response
  File "/home/abwao/.local/lib/python3.6/site-packages/spf/framework.py", line 543, in _run_response_middleware
    _response = await _response
  File "/home/abwao/.local/lib/python3.6/site-packages/sanic_cors/extension.py", line 266, in unapplied_cors_response_middleware
    set_cors_headers(req, resp, context, res_options)
  File "/home/abwao/.local/lib/python3.6/site-packages/sanic_cors/core.py", line 248, in set_cors_headers
    if resp.headers is None:
AttributeError: 'list' object has no attribute 'headers'
2019-07-22 10:56:38,931 [ERROR]  Exception occurred in one of response middleware handlers
Traceback (most recent call last):
  File "/home/abwao/.local/lib/python3.6/site-packages/sanic/app.py", line 958, in handle_request
    request, response
  File "/home/abwao/.local/lib/python3.6/site-packages/spf/framework.py", line 543, in _run_response_middleware
    _response = await _response
  File "/home/abwao/.local/lib/python3.6/site-packages/sanic_cors/extension.py", line 266, in unapplied_cors_response_middleware
    set_cors_headers(req, resp, context, res_options)
  File "/home/abwao/.local/lib/python3.6/site-packages/sanic_cors/core.py", line 248, in set_cors_headers
    if resp.headers is None:
AttributeError: 'list' object has no attribute 'headers'
2019-07-22 10:56:41,891 [ERROR]  Exception occurred in one of response middleware handlers
Traceback (most recent call last):
  File "/home/abwao/.local/lib/python3.6/site-packages/sanic/app.py", line 958, in handle_request
    request, response
  File "/home/abwao/.local/lib/python3.6/site-packages/spf/framework.py", line 543, in _run_response_middleware
    _response = await _response
  File "/home/abwao/.local/lib/python3.6/site-packages/sanic_cors/extension.py", line 266, in unapplied_cors_response_middleware
    set_cors_headers(req, resp, context, res_options)
  File "/home/abwao/.local/lib/python3.6/site-packages/sanic_cors/core.py", line 248, in set_cors_headers
    if resp.headers is None:
AttributeError: 'list' object has no attribute 'headers'
2019-07-22 10:56:56,042 [ERROR]  Exception occurred in one of response middleware handlers
Traceback (most recent call last):
  File "/home/abwao/.local/lib/python3.6/site-packages/sanic/app.py", line 958, in handle_request
    request, response
  File "/home/abwao/.local/lib/python3.6/site-packages/spf/framework.py", line 543, in _run_response_middleware
    _response = await _response
  File "/home/abwao/.local/lib/python3.6/site-packages/sanic_cors/extension.py", line 266, in unapplied_cors_response_middleware
    set_cors_headers(req, resp, context, res_options)
  File "/home/abwao/.local/lib/python3.6/site-packages/sanic_cors/core.py", line 248, in set_cors_headers
    if resp.headers is None:
AttributeError: 'list' object has no attribute 'headers'
2019-07-22 11:00:13,653 [ERROR]  Exception occurred in one of response middleware handlers
Traceback (most recent call last):
  File "/home/abwao/.local/lib/python3.6/site-packages/sanic/app.py", line 958, in handle_request
    request, response
  File "/home/abwao/.local/lib/python3.6/site-packages/spf/framework.py", line 543, in _run_response_middleware
    _response = await _response
  File "/home/abwao/.local/lib/python3.6/site-packages/sanic_cors/extension.py", line 266, in unapplied_cors_response_middleware
    set_cors_headers(req, resp, context, res_options)
  File "/home/abwao/.local/lib/python3.6/site-packages/sanic_cors/core.py", line 248, in set_cors_headers
    if resp.headers is None:
AttributeError: 'list' object has no attribute 'headers'
2019-07-22 11:04:53,512 [ERROR]  Exception occurred in one of response middleware handlers
Traceback (most recent call last):
  File "/home/abwao/.local/lib/python3.6/site-packages/sanic/app.py", line 958, in handle_request
    request, response
  File "/home/abwao/.local/lib/python3.6/site-packages/spf/framework.py", line 543, in _run_response_middleware
    _response = await _response
  File "/home/abwao/.local/lib/python3.6/site-packages/sanic_cors/extension.py", line 266, in unapplied_cors_response_middleware
    set_cors_headers(req, resp, context, res_options)
  File "/home/abwao/.local/lib/python3.6/site-packages/sanic_cors/core.py", line 248, in set_cors_headers
    if resp.headers is None:
AttributeError: 'list' object has no attribute 'headers'
2019-07-22 11:05:03,698 [ERROR]  Exception occurred in one of response middleware handlers
Traceback (most recent call last):
  File "/home/abwao/.local/lib/python3.6/site-packages/sanic/app.py", line 958, in handle_request
    request, response
  File "/home/abwao/.local/lib/python3.6/site-packages/spf/framework.py", line 543, in _run_response_middleware
    _response = await _response
  File "/home/abwao/.local/lib/python3.6/site-packages/sanic_cors/extension.py", line 266, in unapplied_cors_response_middleware
    set_cors_headers(req, resp, context, res_options)
  File "/home/abwao/.local/lib/python3.6/site-packages/sanic_cors/core.py", line 248, in set_cors_headers
    if resp.headers is None:
AttributeError: 'list' object has no attribute 'headers'
2019-07-22 11:07:19,978 [ERROR]  Exception occurred in one of response middleware handlers
Traceback (most recent call last):
  File "/home/abwao/.local/lib/python3.6/site-packages/sanic/app.py", line 958, in handle_request
    request, response
  File "/home/abwao/.local/lib/python3.6/site-packages/spf/framework.py", line 543, in _run_response_middleware
    _response = await _response
  File "/home/abwao/.local/lib/python3.6/site-packages/sanic_cors/extension.py", line 266, in unapplied_cors_response_middleware
    set_cors_headers(req, resp, context, res_options)
  File "/home/abwao/.local/lib/python3.6/site-packages/sanic_cors/core.py", line 248, in set_cors_headers
    if resp.headers is None:
AttributeError: 'list' object has no attribute 'headers'
2019-07-22 11:07:28,852 [ERROR]  Exception occurred in one of response middleware handlers
Traceback (most recent call last):
  File "/home/abwao/.local/lib/python3.6/site-packages/sanic/app.py", line 958, in handle_request
    request, response
  File "/home/abwao/.local/lib/python3.6/site-packages/spf/framework.py", line 543, in _run_response_middleware
    _response = await _response
  File "/home/abwao/.local/lib/python3.6/site-packages/sanic_cors/extension.py", line 266, in unapplied_cors_response_middleware
    set_cors_headers(req, resp, context, res_options)
  File "/home/abwao/.local/lib/python3.6/site-packages/sanic_cors/core.py", line 248, in set_cors_headers
    if resp.headers is None:
AttributeError: 'list' object has no attribute 'headers'
2019-07-22 11:07:32,226 [ERROR]  Exception occurred in one of response middleware handlers
Traceback (most recent call last):
  File "/home/abwao/.local/lib/python3.6/site-packages/sanic/app.py", line 958, in handle_request
    request, response
  File "/home/abwao/.local/lib/python3.6/site-packages/spf/framework.py", line 543, in _run_response_middleware
    _response = await _response
  File "/home/abwao/.local/lib/python3.6/site-packages/sanic_cors/extension.py", line 266, in unapplied_cors_response_middleware
    set_cors_headers(req, resp, context, res_options)
  File "/home/abwao/.local/lib/python3.6/site-packages/sanic_cors/core.py", line 248, in set_cors_headers
    if resp.headers is None:
AttributeError: 'list' object has no attribute 'headers'
2019-07-22 11:07:41,703 [ERROR]  Exception occurred in one of response middleware handlers
Traceback (most recent call last):
  File "/home/abwao/.local/lib/python3.6/site-packages/sanic/app.py", line 958, in handle_request
    request, response
  File "/home/abwao/.local/lib/python3.6/site-packages/spf/framework.py", line 543, in _run_response_middleware
    _response = await _response
  File "/home/abwao/.local/lib/python3.6/site-packages/sanic_cors/extension.py", line 266, in unapplied_cors_response_middleware
    set_cors_headers(req, resp, context, res_options)
  File "/home/abwao/.local/lib/python3.6/site-packages/sanic_cors/core.py", line 248, in set_cors_headers
    if resp.headers is None:
AttributeError: 'list' object has no attribute 'headers'
2019-07-22 11:25:14,052 [ERROR]  Exception occurred in one of response middleware handlers
Traceback (most recent call last):
  File "/home/abwao/.local/lib/python3.6/site-packages/sanic/app.py", line 958, in handle_request
    request, response
  File "/home/abwao/.local/lib/python3.6/site-packages/spf/framework.py", line 543, in _run_response_middleware
    _response = await _response
  File "/home/abwao/.local/lib/python3.6/site-packages/sanic_cors/extension.py", line 266, in unapplied_cors_response_middleware
    set_cors_headers(req, resp, context, res_options)
  File "/home/abwao/.local/lib/python3.6/site-packages/sanic_cors/core.py", line 248, in set_cors_headers
    if resp.headers is None:
AttributeError: 'list' object has no attribute 'headers'
2019-07-22 11:41:14,979 [ERROR]  Exception occurred in one of response middleware handlers
Traceback (most recent call last):
  File "/home/abwao/.local/lib/python3.6/site-packages/sanic/app.py", line 958, in handle_request
    request, response
  File "/home/abwao/.local/lib/python3.6/site-packages/spf/framework.py", line 543, in _run_response_middleware
    _response = await _response
  File "/home/abwao/.local/lib/python3.6/site-packages/sanic_cors/extension.py", line 266, in unapplied_cors_response_middleware
    set_cors_headers(req, resp, context, res_options)
  File "/home/abwao/.local/lib/python3.6/site-packages/sanic_cors/core.py", line 248, in set_cors_headers
    if resp.headers is None:
AttributeError: 'list' object has no attribute 'headers'
2019-07-22 11:47:35,540 [ERROR]  Exception occurred in one of response middleware handlers
Traceback (most recent call last):
  File "/home/abwao/.local/lib/python3.6/site-packages/sanic/app.py", line 958, in handle_request
    request, response
  File "/home/abwao/.local/lib/python3.6/site-packages/spf/framework.py", line 543, in _run_response_middleware
    _response = await _response
  File "/home/abwao/.local/lib/python3.6/site-packages/sanic_cors/extension.py", line 266, in unapplied_cors_response_middleware
    set_cors_headers(req, resp, context, res_options)
  File "/home/abwao/.local/lib/python3.6/site-packages/sanic_cors/core.py", line 248, in set_cors_headers
    if resp.headers is None:
AttributeError: 'list' object has no attribute 'headers'
2019-07-22 11:59:23,653 [ERROR]  Exception occurred in one of response middleware handlers
Traceback (most recent call last):
  File "/home/abwao/.local/lib/python3.6/site-packages/sanic/app.py", line 958, in handle_request
    request, response
  File "/home/abwao/.local/lib/python3.6/site-packages/spf/framework.py", line 543, in _run_response_middleware
    _response = await _response
  File "/home/abwao/.local/lib/python3.6/site-packages/sanic_cors/extension.py", line 266, in unapplied_cors_response_middleware
    set_cors_headers(req, resp, context, res_options)
  File "/home/abwao/.local/lib/python3.6/site-packages/sanic_cors/core.py", line 248, in set_cors_headers
    if resp.headers is None:
AttributeError: 'list' object has no attribute 'headers'
2019-07-22 11:59:26,653 [ERROR]  Exception occurred in one of response middleware handlers
Traceback (most recent call last):
  File "/home/abwao/.local/lib/python3.6/site-packages/sanic/app.py", line 958, in handle_request
    request, response
  File "/home/abwao/.local/lib/python3.6/site-packages/spf/framework.py", line 543, in _run_response_middleware
    _response = await _response
  File "/home/abwao/.local/lib/python3.6/site-packages/sanic_cors/extension.py", line 266, in unapplied_cors_response_middleware
    set_cors_headers(req, resp, context, res_options)
  File "/home/abwao/.local/lib/python3.6/site-packages/sanic_cors/core.py", line 248, in set_cors_headers
    if resp.headers is None:
AttributeError: 'list' object has no attribute 'headers'
2019-07-22 12:00:20,188 [ERROR]  Exception occurred in one of response middleware handlers
Traceback (most recent call last):
  File "/home/abwao/.local/lib/python3.6/site-packages/sanic/app.py", line 958, in handle_request
    request, response
  File "/home/abwao/.local/lib/python3.6/site-packages/spf/framework.py", line 543, in _run_response_middleware
    _response = await _response
  File "/home/abwao/.local/lib/python3.6/site-packages/sanic_cors/extension.py", line 266, in unapplied_cors_response_middleware
    set_cors_headers(req, resp, context, res_options)
  File "/home/abwao/.local/lib/python3.6/site-packages/sanic_cors/core.py", line 248, in set_cors_headers
    if resp.headers is None:
AttributeError: 'list' object has no attribute 'headers'
2019-07-22 12:00:22,500 [ERROR]  Exception occurred in one of response middleware handlers
Traceback (most recent call last):
  File "/home/abwao/.local/lib/python3.6/site-packages/sanic/app.py", line 958, in handle_request
    request, response
  File "/home/abwao/.local/lib/python3.6/site-packages/spf/framework.py", line 543, in _run_response_middleware
    _response = await _response
  File "/home/abwao/.local/lib/python3.6/site-packages/sanic_cors/extension.py", line 266, in unapplied_cors_response_middleware
    set_cors_headers(req, resp, context, res_options)
  File "/home/abwao/.local/lib/python3.6/site-packages/sanic_cors/core.py", line 248, in set_cors_headers
    if resp.headers is None:
AttributeError: 'list' object has no attribute 'headers'
2019-07-22 12:01:10,416 [ERROR]  Exception occurred in one of response middleware handlers
Traceback (most recent call last):
  File "/home/abwao/.local/lib/python3.6/site-packages/sanic/app.py", line 958, in handle_request
    request, response
  File "/home/abwao/.local/lib/python3.6/site-packages/spf/framework.py", line 543, in _run_response_middleware
    _response = await _response
  File "/home/abwao/.local/lib/python3.6/site-packages/sanic_cors/extension.py", line 266, in unapplied_cors_response_middleware
    set_cors_headers(req, resp, context, res_options)
  File "/home/abwao/.local/lib/python3.6/site-packages/sanic_cors/core.py", line 248, in set_cors_headers
    if resp.headers is None:
AttributeError: 'list' object has no attribute 'headers'
2019-07-22 12:01:12,591 [ERROR]  Exception occurred in one of response middleware handlers
Traceback (most recent call last):
  File "/home/abwao/.local/lib/python3.6/site-packages/sanic/app.py", line 958, in handle_request
    request, response
  File "/home/abwao/.local/lib/python3.6/site-packages/spf/framework.py", line 543, in _run_response_middleware
    _response = await _response
  File "/home/abwao/.local/lib/python3.6/site-packages/sanic_cors/extension.py", line 266, in unapplied_cors_response_middleware
    set_cors_headers(req, resp, context, res_options)
  File "/home/abwao/.local/lib/python3.6/site-packages/sanic_cors/core.py", line 248, in set_cors_headers
    if resp.headers is None:
AttributeError: 'list' object has no attribute 'headers'
2019-07-22 12:02:26,112 [ERROR]  Exception occurred in one of response middleware handlers
Traceback (most recent call last):
  File "/home/abwao/.local/lib/python3.6/site-packages/sanic/app.py", line 958, in handle_request
    request, response
  File "/home/abwao/.local/lib/python3.6/site-packages/spf/framework.py", line 543, in _run_response_middleware
    _response = await _response
  File "/home/abwao/.local/lib/python3.6/site-packages/sanic_cors/extension.py", line 266, in unapplied_cors_response_middleware
    set_cors_headers(req, resp, context, res_options)
  File "/home/abwao/.local/lib/python3.6/site-packages/sanic_cors/core.py", line 248, in set_cors_headers
    if resp.headers is None:
AttributeError: 'list' object has no attribute 'headers'
2019-07-22 12:02:33,822 [ERROR]  Exception occurred in one of response middleware handlers
Traceback (most recent call last):
  File "/home/abwao/.local/lib/python3.6/site-packages/sanic/app.py", line 958, in handle_request
    request, response
  File "/home/abwao/.local/lib/python3.6/site-packages/spf/framework.py", line 543, in _run_response_middleware
    _response = await _response
  File "/home/abwao/.local/lib/python3.6/site-packages/sanic_cors/extension.py", line 266, in unapplied_cors_response_middleware
    set_cors_headers(req, resp, context, res_options)
  File "/home/abwao/.local/lib/python3.6/site-packages/sanic_cors/core.py", line 248, in set_cors_headers
    if resp.headers is None:
AttributeError: 'list' object has no attribute 'headers'
2019-07-22 12:03:46,770 [ERROR]  Exception occurred in one of response middleware handlers
Traceback (most recent call last):
  File "/home/abwao/.local/lib/python3.6/site-packages/sanic/app.py", line 958, in handle_request
    request, response
  File "/home/abwao/.local/lib/python3.6/site-packages/spf/framework.py", line 543, in _run_response_middleware
    _response = await _response
  File "/home/abwao/.local/lib/python3.6/site-packages/sanic_cors/extension.py", line 266, in unapplied_cors_response_middleware
    set_cors_headers(req, resp, context, res_options)
  File "/home/abwao/.local/lib/python3.6/site-packages/sanic_cors/core.py", line 248, in set_cors_headers
    if resp.headers is None:
AttributeError: 'list' object has no attribute 'headers'
2019-07-22 12:03:58,108 [ERROR]  Exception occurred in one of response middleware handlers
Traceback (most recent call last):
  File "/home/abwao/.local/lib/python3.6/site-packages/sanic/app.py", line 958, in handle_request
    request, response
  File "/home/abwao/.local/lib/python3.6/site-packages/spf/framework.py", line 543, in _run_response_middleware
    _response = await _response
  File "/home/abwao/.local/lib/python3.6/site-packages/sanic_cors/extension.py", line 266, in unapplied_cors_response_middleware
    set_cors_headers(req, resp, context, res_options)
  File "/home/abwao/.local/lib/python3.6/site-packages/sanic_cors/core.py", line 248, in set_cors_headers
    if resp.headers is None:
AttributeError: 'list' object has no attribute 'headers'
2019-07-22 12:05:25,635 [ERROR]  Exception occurred in one of response middleware handlers
Traceback (most recent call last):
  File "/home/abwao/.local/lib/python3.6/site-packages/sanic/app.py", line 958, in handle_request
    request, response
  File "/home/abwao/.local/lib/python3.6/site-packages/spf/framework.py", line 543, in _run_response_middleware
    _response = await _response
  File "/home/abwao/.local/lib/python3.6/site-packages/sanic_cors/extension.py", line 266, in unapplied_cors_response_middleware
    set_cors_headers(req, resp, context, res_options)
  File "/home/abwao/.local/lib/python3.6/site-packages/sanic_cors/core.py", line 248, in set_cors_headers
    if resp.headers is None:
AttributeError: 'list' object has no attribute 'headers'
2019-07-22 12:05:37,162 [ERROR]  Exception occurred in one of response middleware handlers
Traceback (most recent call last):
  File "/home/abwao/.local/lib/python3.6/site-packages/sanic/app.py", line 958, in handle_request
    request, response
  File "/home/abwao/.local/lib/python3.6/site-packages/spf/framework.py", line 543, in _run_response_middleware
    _response = await _response
  File "/home/abwao/.local/lib/python3.6/site-packages/sanic_cors/extension.py", line 266, in unapplied_cors_response_middleware
    set_cors_headers(req, resp, context, res_options)
  File "/home/abwao/.local/lib/python3.6/site-packages/sanic_cors/core.py", line 248, in set_cors_headers
    if resp.headers is None:
AttributeError: 'list' object has no attribute 'headers'
2019-07-22 12:05:41,773 [ERROR]  Exception occurred in one of response middleware handlers
Traceback (most recent call last):
  File "/home/abwao/.local/lib/python3.6/site-packages/sanic/app.py", line 958, in handle_request
    request, response
  File "/home/abwao/.local/lib/python3.6/site-packages/spf/framework.py", line 543, in _run_response_middleware
    _response = await _response
  File "/home/abwao/.local/lib/python3.6/site-packages/sanic_cors/extension.py", line 266, in unapplied_cors_response_middleware
    set_cors_headers(req, resp, context, res_options)
  File "/home/abwao/.local/lib/python3.6/site-packages/sanic_cors/core.py", line 248, in set_cors_headers
    if resp.headers is None:
AttributeError: 'list' object has no attribute 'headers'
2019-07-22 12:10:19,248 [ERROR]  Exception occurred in one of response middleware handlers
Traceback (most recent call last):
  File "/home/abwao/.local/lib/python3.6/site-packages/sanic/app.py", line 958, in handle_request
    request, response
  File "/home/abwao/.local/lib/python3.6/site-packages/spf/framework.py", line 543, in _run_response_middleware
    _response = await _response
  File "/home/abwao/.local/lib/python3.6/site-packages/sanic_cors/extension.py", line 266, in unapplied_cors_response_middleware
    set_cors_headers(req, resp, context, res_options)
  File "/home/abwao/.local/lib/python3.6/site-packages/sanic_cors/core.py", line 248, in set_cors_headers
    if resp.headers is None:
AttributeError: 'list' object has no attribute 'headers'
2019-07-22 12:10:50,257 [ERROR]  Exception occurred in one of response middleware handlers
Traceback (most recent call last):
  File "/home/abwao/.local/lib/python3.6/site-packages/sanic/app.py", line 958, in handle_request
    request, response
  File "/home/abwao/.local/lib/python3.6/site-packages/spf/framework.py", line 543, in _run_response_middleware
    _response = await _response
  File "/home/abwao/.local/lib/python3.6/site-packages/sanic_cors/extension.py", line 266, in unapplied_cors_response_middleware
    set_cors_headers(req, resp, context, res_options)
  File "/home/abwao/.local/lib/python3.6/site-packages/sanic_cors/core.py", line 248, in set_cors_headers
    if resp.headers is None:
AttributeError: 'list' object has no attribute 'headers'
2019-07-22 12:37:35,743 [ERROR]  Exception occurred in one of response middleware handlers
Traceback (most recent call last):
  File "/home/abwao/.local/lib/python3.6/site-packages/sanic/app.py", line 958, in handle_request
    request, response
  File "/home/abwao/.local/lib/python3.6/site-packages/spf/framework.py", line 543, in _run_response_middleware
    _response = await _response
  File "/home/abwao/.local/lib/python3.6/site-packages/sanic_cors/extension.py", line 266, in unapplied_cors_response_middleware
    set_cors_headers(req, resp, context, res_options)
  File "/home/abwao/.local/lib/python3.6/site-packages/sanic_cors/core.py", line 248, in set_cors_headers
    if resp.headers is None:
AttributeError: 'list' object has no attribute 'headers'
2019-07-22 12:41:31,592 [ERROR]  Exception occurred while handling uri: 'http://a297d403.ngrok.io/'
Traceback (most recent call last):
  File "/home/abwao/.local/lib/python3.6/site-packages/sanic/app.py", line 893, in handle_request
    handler, args, kwargs, uri = self.router.get(request)
  File "/home/abwao/.local/lib/python3.6/site-packages/sanic/router.py", line 407, in get
    return self._get(request.path, request.method, "")
  File "/home/abwao/.local/lib/python3.6/site-packages/sanic/router.py", line 469, in _get
    raise NotFound("Requested URL {} not found".format(url))
sanic.exceptions.NotFound: Requested URL / not found
2019-07-22 12:41:32,320 [ERROR]  Exception occurred while handling uri: 'http://a297d403.ngrok.io/favicon.ico'
Traceback (most recent call last):
  File "/home/abwao/.local/lib/python3.6/site-packages/sanic/app.py", line 893, in handle_request
    handler, args, kwargs, uri = self.router.get(request)
  File "/home/abwao/.local/lib/python3.6/site-packages/sanic/router.py", line 407, in get
    return self._get(request.path, request.method, "")
  File "/home/abwao/.local/lib/python3.6/site-packages/sanic/router.py", line 469, in _get
    raise NotFound("Requested URL {} not found".format(url))
sanic.exceptions.NotFound: Requested URL /favicon.ico not found
2019-07-22 12:45:11,285 [ERROR]  Exception occurred while handling uri: 'http://localhost:5005/version'
Traceback (most recent call last):
  File "/home/abwao/.local/lib/python3.6/site-packages/sanic/app.py", line 893, in handle_request
    handler, args, kwargs, uri = self.router.get(request)
  File "/home/abwao/.local/lib/python3.6/site-packages/sanic/router.py", line 407, in get
    return self._get(request.path, request.method, "")
  File "/home/abwao/.local/lib/python3.6/site-packages/sanic/router.py", line 469, in _get
    raise NotFound("Requested URL {} not found".format(url))
sanic.exceptions.NotFound: Requested URL /version not found
2019-07-22 12:50:45,688 [ERROR]  Exception occurred in one of response middleware handlers
Traceback (most recent call last):
  File "/home/abwao/.local/lib/python3.6/site-packages/sanic/app.py", line 958, in handle_request
    request, response
  File "/home/abwao/.local/lib/python3.6/site-packages/spf/framework.py", line 543, in _run_response_middleware
    _response = await _response
  File "/home/abwao/.local/lib/python3.6/site-packages/sanic_cors/extension.py", line 266, in unapplied_cors_response_middleware
    set_cors_headers(req, resp, context, res_options)
  File "/home/abwao/.local/lib/python3.6/site-packages/sanic_cors/core.py", line 248, in set_cors_headers
    if resp.headers is None:
AttributeError: 'list' object has no attribute 'headers'
2019-07-22 12:52:04,054 [ERROR]  Exception occurred while handling uri: 'http://localhost:5005/version'
Traceback (most recent call last):
  File "/home/abwao/.local/lib/python3.6/site-packages/sanic/app.py", line 893, in handle_request
    handler, args, kwargs, uri = self.router.get(request)
  File "/home/abwao/.local/lib/python3.6/site-packages/sanic/router.py", line 407, in get
    return self._get(request.path, request.method, "")
  File "/home/abwao/.local/lib/python3.6/site-packages/sanic/router.py", line 469, in _get
    raise NotFound("Requested URL {} not found".format(url))
sanic.exceptions.NotFound: Requested URL /version not found
2019-07-22 12:57:15,457 [ERROR]  Exception occurred in one of response middleware handlers
Traceback (most recent call last):
  File "/home/abwao/.local/lib/python3.6/site-packages/sanic/app.py", line 958, in handle_request
    request, response
  File "/home/abwao/.local/lib/python3.6/site-packages/spf/framework.py", line 543, in _run_response_middleware
    _response = await _response
  File "/home/abwao/.local/lib/python3.6/site-packages/sanic_cors/extension.py", line 266, in unapplied_cors_response_middleware
    set_cors_headers(req, resp, context, res_options)
  File "/home/abwao/.local/lib/python3.6/site-packages/sanic_cors/core.py", line 248, in set_cors_headers
    if resp.headers is None:
AttributeError: 'list' object has no attribute 'headers'
2019-07-22 12:57:24,330 [ERROR]  Exception occurred in one of response middleware handlers
Traceback (most recent call last):
  File "/home/abwao/.local/lib/python3.6/site-packages/sanic/app.py", line 958, in handle_request
    request, response
  File "/home/abwao/.local/lib/python3.6/site-packages/spf/framework.py", line 543, in _run_response_middleware
    _response = await _response
  File "/home/abwao/.local/lib/python3.6/site-packages/sanic_cors/extension.py", line 266, in unapplied_cors_response_middleware
    set_cors_headers(req, resp, context, res_options)
  File "/home/abwao/.local/lib/python3.6/site-packages/sanic_cors/core.py", line 248, in set_cors_headers
    if resp.headers is None:
AttributeError: 'list' object has no attribute 'headers'
2019-07-22 12:58:25,513 [ERROR]  Exception occurred in one of response middleware handlers
Traceback (most recent call last):
  File "/home/abwao/.local/lib/python3.6/site-packages/sanic/app.py", line 958, in handle_request
    request, response
  File "/home/abwao/.local/lib/python3.6/site-packages/spf/framework.py", line 543, in _run_response_middleware
    _response = await _response
  File "/home/abwao/.local/lib/python3.6/site-packages/sanic_cors/extension.py", line 266, in unapplied_cors_response_middleware
    set_cors_headers(req, resp, context, res_options)
  File "/home/abwao/.local/lib/python3.6/site-packages/sanic_cors/core.py", line 248, in set_cors_headers
    if resp.headers is None:
AttributeError: 'list' object has no attribute 'headers'
2019-07-22 12:58:29,463 [ERROR]  Exception occurred in one of response middleware handlers
Traceback (most recent call last):
  File "/home/abwao/.local/lib/python3.6/site-packages/sanic/app.py", line 958, in handle_request
    request, response
  File "/home/abwao/.local/lib/python3.6/site-packages/spf/framework.py", line 543, in _run_response_middleware
    _response = await _response
  File "/home/abwao/.local/lib/python3.6/site-packages/sanic_cors/extension.py", line 266, in unapplied_cors_response_middleware
    set_cors_headers(req, resp, context, res_options)
  File "/home/abwao/.local/lib/python3.6/site-packages/sanic_cors/core.py", line 248, in set_cors_headers
    if resp.headers is None:
AttributeError: 'list' object has no attribute 'headers'
2019-07-22 13:02:43,345 [ERROR]  Exception occurred in one of response middleware handlers
Traceback (most recent call last):
  File "/home/abwao/.local/lib/python3.6/site-packages/sanic/app.py", line 958, in handle_request
    request, response
  File "/home/abwao/.local/lib/python3.6/site-packages/spf/framework.py", line 543, in _run_response_middleware
    _response = await _response
  File "/home/abwao/.local/lib/python3.6/site-packages/sanic_cors/extension.py", line 266, in unapplied_cors_response_middleware
    set_cors_headers(req, resp, context, res_options)
  File "/home/abwao/.local/lib/python3.6/site-packages/sanic_cors/core.py", line 248, in set_cors_headers
    if resp.headers is None:
AttributeError: 'list' object has no attribute 'headers'
2019-07-22 13:06:33,061 [ERROR]  Exception occurred in one of response middleware handlers
Traceback (most recent call last):
  File "/home/abwao/.local/lib/python3.6/site-packages/sanic/app.py", line 958, in handle_request
    request, response
  File "/home/abwao/.local/lib/python3.6/site-packages/spf/framework.py", line 543, in _run_response_middleware
    _response = await _response
  File "/home/abwao/.local/lib/python3.6/site-packages/sanic_cors/extension.py", line 266, in unapplied_cors_response_middleware
    set_cors_headers(req, resp, context, res_options)
  File "/home/abwao/.local/lib/python3.6/site-packages/sanic_cors/core.py", line 248, in set_cors_headers
    if resp.headers is None:
AttributeError: 'list' object has no attribute 'headers'
2019-07-22 13:06:41,126 [ERROR]  Exception occurred in one of response middleware handlers
Traceback (most recent call last):
  File "/home/abwao/.local/lib/python3.6/site-packages/sanic/app.py", line 958, in handle_request
    request, response
  File "/home/abwao/.local/lib/python3.6/site-packages/spf/framework.py", line 543, in _run_response_middleware
    _response = await _response
  File "/home/abwao/.local/lib/python3.6/site-packages/sanic_cors/extension.py", line 266, in unapplied_cors_response_middleware
    set_cors_headers(req, resp, context, res_options)
  File "/home/abwao/.local/lib/python3.6/site-packages/sanic_cors/core.py", line 248, in set_cors_headers
    if resp.headers is None:
AttributeError: 'list' object has no attribute 'headers'
2019-07-22 13:15:47,376 [ERROR]  Exception occurred in one of response middleware handlers
Traceback (most recent call last):
  File "/home/abwao/.local/lib/python3.6/site-packages/sanic/app.py", line 958, in handle_request
    request, response
  File "/home/abwao/.local/lib/python3.6/site-packages/spf/framework.py", line 543, in _run_response_middleware
    _response = await _response
  File "/home/abwao/.local/lib/python3.6/site-packages/sanic_cors/extension.py", line 266, in unapplied_cors_response_middleware
    set_cors_headers(req, resp, context, res_options)
  File "/home/abwao/.local/lib/python3.6/site-packages/sanic_cors/core.py", line 248, in set_cors_headers
    if resp.headers is None:
AttributeError: 'list' object has no attribute 'headers'
2019-07-22 13:23:18,288 [ERROR]  Exception occurred in one of response middleware handlers
Traceback (most recent call last):
  File "/home/abwao/.local/lib/python3.6/site-packages/sanic/app.py", line 958, in handle_request
    request, response
  File "/home/abwao/.local/lib/python3.6/site-packages/spf/framework.py", line 543, in _run_response_middleware
    _response = await _response
  File "/home/abwao/.local/lib/python3.6/site-packages/sanic_cors/extension.py", line 266, in unapplied_cors_response_middleware
    set_cors_headers(req, resp, context, res_options)
  File "/home/abwao/.local/lib/python3.6/site-packages/sanic_cors/core.py", line 248, in set_cors_headers
    if resp.headers is None:
AttributeError: 'list' object has no attribute 'headers'
2019-07-22 13:36:17,209 [ERROR]  Exception occurred in one of response middleware handlers
Traceback (most recent call last):
  File "/home/abwao/.local/lib/python3.6/site-packages/sanic/app.py", line 958, in handle_request
    request, response
  File "/home/abwao/.local/lib/python3.6/site-packages/spf/framework.py", line 543, in _run_response_middleware
    _response = await _response
  File "/home/abwao/.local/lib/python3.6/site-packages/sanic_cors/extension.py", line 266, in unapplied_cors_response_middleware
    set_cors_headers(req, resp, context, res_options)
  File "/home/abwao/.local/lib/python3.6/site-packages/sanic_cors/core.py", line 248, in set_cors_headers
    if resp.headers is None:
AttributeError: 'list' object has no attribute 'headers'
2019-07-22 13:36:26,478 [ERROR]  Exception occurred in one of response middleware handlers
Traceback (most recent call last):
  File "/home/abwao/.local/lib/python3.6/site-packages/sanic/app.py", line 958, in handle_request
    request, response
  File "/home/abwao/.local/lib/python3.6/site-packages/spf/framework.py", line 543, in _run_response_middleware
    _response = await _response
  File "/home/abwao/.local/lib/python3.6/site-packages/sanic_cors/extension.py", line 266, in unapplied_cors_response_middleware
    set_cors_headers(req, resp, context, res_options)
  File "/home/abwao/.local/lib/python3.6/site-packages/sanic_cors/core.py", line 248, in set_cors_headers
    if resp.headers is None:
AttributeError: 'list' object has no attribute 'headers'
2019-07-22 21:25:56,444 [ERROR]  Exception occurred while handling uri: unknown
Traceback (most recent call last):
  File "/home/abwao/.local/lib/python3.6/site-packages/sanic/server.py", line 267, in data_received
    self.parser.feed_data(data)
  File "httptools/parser/parser.pyx", line 193, in httptools.parser.parser.HttpParser.feed_data
httptools.parser.errors.HttpParserInvalidMethodError: invalid HTTP method
2019-07-22 21:25:56,480 [ERROR]  Exception occurred while handling uri: unknown
Traceback (most recent call last):
  File "/home/abwao/.local/lib/python3.6/site-packages/sanic/server.py", line 267, in data_received
    self.parser.feed_data(data)
  File "httptools/parser/parser.pyx", line 193, in httptools.parser.parser.HttpParser.feed_data
httptools.parser.errors.HttpParserInvalidMethodError: invalid HTTP method
2019-07-22 21:25:57,690 [ERROR]  Exception occurred while handling uri: unknown
Traceback (most recent call last):
  File "/home/abwao/.local/lib/python3.6/site-packages/sanic/server.py", line 267, in data_received
    self.parser.feed_data(data)
  File "httptools/parser/parser.pyx", line 193, in httptools.parser.parser.HttpParser.feed_data
httptools.parser.errors.HttpParserInvalidMethodError: invalid HTTP method
2019-07-22 21:25:57,693 [ERROR]  Exception occurred while handling uri: unknown
Traceback (most recent call last):
  File "/home/abwao/.local/lib/python3.6/site-packages/sanic/server.py", line 267, in data_received
    self.parser.feed_data(data)
  File "httptools/parser/parser.pyx", line 193, in httptools.parser.parser.HttpParser.feed_data
httptools.parser.errors.HttpParserInvalidMethodError: invalid HTTP method
2019-07-22 21:25:59,217 [ERROR]  Exception occurred while handling uri: unknown
Traceback (most recent call last):
  File "/home/abwao/.local/lib/python3.6/site-packages/sanic/server.py", line 267, in data_received
    self.parser.feed_data(data)
  File "httptools/parser/parser.pyx", line 193, in httptools.parser.parser.HttpParser.feed_data
httptools.parser.errors.HttpParserInvalidMethodError: invalid HTTP method
2019-07-22 21:25:59,219 [ERROR]  Exception occurred while handling uri: unknown
Traceback (most recent call last):
  File "/home/abwao/.local/lib/python3.6/site-packages/sanic/server.py", line 267, in data_received
    self.parser.feed_data(data)
  File "httptools/parser/parser.pyx", line 193, in httptools.parser.parser.HttpParser.feed_data
httptools.parser.errors.HttpParserInvalidMethodError: invalid HTTP method
2019-07-22 21:25:59,967 [ERROR]  Exception occurred while handling uri: unknown
Traceback (most recent call last):
  File "/home/abwao/.local/lib/python3.6/site-packages/sanic/server.py", line 267, in data_received
    self.parser.feed_data(data)
  File "httptools/parser/parser.pyx", line 193, in httptools.parser.parser.HttpParser.feed_data
httptools.parser.errors.HttpParserInvalidMethodError: invalid HTTP method
2019-07-22 21:25:59,968 [ERROR]  Exception occurred while handling uri: unknown
Traceback (most recent call last):
  File "/home/abwao/.local/lib/python3.6/site-packages/sanic/server.py", line 267, in data_received
    self.parser.feed_data(data)
  File "httptools/parser/parser.pyx", line 193, in httptools.parser.parser.HttpParser.feed_data
httptools.parser.errors.HttpParserInvalidMethodError: invalid HTTP method
2019-07-22 21:26:01,725 [ERROR]  Exception occurred while handling uri: unknown
Traceback (most recent call last):
  File "/home/abwao/.local/lib/python3.6/site-packages/sanic/server.py", line 267, in data_received
    self.parser.feed_data(data)
  File "httptools/parser/parser.pyx", line 193, in httptools.parser.parser.HttpParser.feed_data
httptools.parser.errors.HttpParserInvalidMethodError: invalid HTTP method
2019-07-22 21:26:01,728 [ERROR]  Exception occurred while handling uri: unknown
Traceback (most recent call last):
  File "/home/abwao/.local/lib/python3.6/site-packages/sanic/server.py", line 267, in data_received
    self.parser.feed_data(data)
  File "httptools/parser/parser.pyx", line 193, in httptools.parser.parser.HttpParser.feed_data
httptools.parser.errors.HttpParserInvalidMethodError: invalid HTTP method
2019-07-22 21:26:03,980 [ERROR]  Exception occurred while handling uri: unknown
Traceback (most recent call last):
  File "/home/abwao/.local/lib/python3.6/site-packages/sanic/server.py", line 267, in data_received
    self.parser.feed_data(data)
  File "httptools/parser/parser.pyx", line 193, in httptools.parser.parser.HttpParser.feed_data
httptools.parser.errors.HttpParserInvalidMethodError: invalid HTTP method
2019-07-22 21:26:03,982 [ERROR]  Exception occurred while handling uri: unknown
Traceback (most recent call last):
  File "/home/abwao/.local/lib/python3.6/site-packages/sanic/server.py", line 267, in data_received
    self.parser.feed_data(data)
  File "httptools/parser/parser.pyx", line 193, in httptools.parser.parser.HttpParser.feed_data
httptools.parser.errors.HttpParserInvalidMethodError: invalid HTTP method
2019-07-22 21:26:09,043 [ERROR]  Exception occurred while handling uri: unknown
Traceback (most recent call last):
  File "/home/abwao/.local/lib/python3.6/site-packages/sanic/server.py", line 267, in data_received
    self.parser.feed_data(data)
  File "httptools/parser/parser.pyx", line 193, in httptools.parser.parser.HttpParser.feed_data
httptools.parser.errors.HttpParserInvalidMethodError: invalid HTTP method
2019-07-22 21:26:09,045 [ERROR]  Exception occurred while handling uri: unknown
Traceback (most recent call last):
  File "/home/abwao/.local/lib/python3.6/site-packages/sanic/server.py", line 267, in data_received
    self.parser.feed_data(data)
  File "httptools/parser/parser.pyx", line 193, in httptools.parser.parser.HttpParser.feed_data
httptools.parser.errors.HttpParserInvalidMethodError: invalid HTTP method
2019-07-22 21:26:15,044 [ERROR]  Exception occurred while handling uri: unknown
Traceback (most recent call last):
  File "/home/abwao/.local/lib/python3.6/site-packages/sanic/server.py", line 267, in data_received
    self.parser.feed_data(data)
  File "httptools/parser/parser.pyx", line 193, in httptools.parser.parser.HttpParser.feed_data
httptools.parser.errors.HttpParserInvalidMethodError: invalid HTTP method
2019-07-22 21:26:15,046 [ERROR]  Exception occurred while handling uri: unknown
Traceback (most recent call last):
  File "/home/abwao/.local/lib/python3.6/site-packages/sanic/server.py", line 267, in data_received
    self.parser.feed_data(data)
  File "httptools/parser/parser.pyx", line 193, in httptools.parser.parser.HttpParser.feed_data
httptools.parser.errors.HttpParserInvalidMethodError: invalid HTTP method
2019-07-22 21:26:21,044 [ERROR]  Exception occurred while handling uri: unknown
Traceback (most recent call last):
  File "/home/abwao/.local/lib/python3.6/site-packages/sanic/server.py", line 267, in data_received
    self.parser.feed_data(data)
  File "httptools/parser/parser.pyx", line 193, in httptools.parser.parser.HttpParser.feed_data
httptools.parser.errors.HttpParserInvalidMethodError: invalid HTTP method
2019-07-22 21:26:21,047 [ERROR]  Exception occurred while handling uri: unknown
Traceback (most recent call last):
  File "/home/abwao/.local/lib/python3.6/site-packages/sanic/server.py", line 267, in data_received
    self.parser.feed_data(data)
  File "httptools/parser/parser.pyx", line 193, in httptools.parser.parser.HttpParser.feed_data
httptools.parser.errors.HttpParserInvalidMethodError: invalid HTTP method
2019-07-22 21:26:27,044 [ERROR]  Exception occurred while handling uri: unknown
Traceback (most recent call last):
  File "/home/abwao/.local/lib/python3.6/site-packages/sanic/server.py", line 267, in data_received
    self.parser.feed_data(data)
  File "httptools/parser/parser.pyx", line 193, in httptools.parser.parser.HttpParser.feed_data
httptools.parser.errors.HttpParserInvalidMethodError: invalid HTTP method
2019-07-22 21:26:27,046 [ERROR]  Exception occurred while handling uri: unknown
Traceback (most recent call last):
  File "/home/abwao/.local/lib/python3.6/site-packages/sanic/server.py", line 267, in data_received
    self.parser.feed_data(data)
  File "httptools/parser/parser.pyx", line 193, in httptools.parser.parser.HttpParser.feed_data
httptools.parser.errors.HttpParserInvalidMethodError: invalid HTTP method
2019-07-22 21:26:33,044 [ERROR]  Exception occurred while handling uri: unknown
Traceback (most recent call last):
  File "/home/abwao/.local/lib/python3.6/site-packages/sanic/server.py", line 267, in data_received
    self.parser.feed_data(data)
  File "httptools/parser/parser.pyx", line 193, in httptools.parser.parser.HttpParser.feed_data
httptools.parser.errors.HttpParserInvalidMethodError: invalid HTTP method
2019-07-22 21:26:33,047 [ERROR]  Exception occurred while handling uri: unknown
Traceback (most recent call last):
  File "/home/abwao/.local/lib/python3.6/site-packages/sanic/server.py", line 267, in data_received
    self.parser.feed_data(data)
  File "httptools/parser/parser.pyx", line 193, in httptools.parser.parser.HttpParser.feed_data
httptools.parser.errors.HttpParserInvalidMethodError: invalid HTTP method
2019-07-22 21:26:39,044 [ERROR]  Exception occurred while handling uri: unknown
Traceback (most recent call last):
  File "/home/abwao/.local/lib/python3.6/site-packages/sanic/server.py", line 267, in data_received
    self.parser.feed_data(data)
  File "httptools/parser/parser.pyx", line 193, in httptools.parser.parser.HttpParser.feed_data
httptools.parser.errors.HttpParserInvalidMethodError: invalid HTTP method
2019-07-22 21:26:39,047 [ERROR]  Exception occurred while handling uri: unknown
Traceback (most recent call last):
  File "/home/abwao/.local/lib/python3.6/site-packages/sanic/server.py", line 267, in data_received
    self.parser.feed_data(data)
  File "httptools/parser/parser.pyx", line 193, in httptools.parser.parser.HttpParser.feed_data
httptools.parser.errors.HttpParserInvalidMethodError: invalid HTTP method
2019-07-22 21:26:45,043 [ERROR]  Exception occurred while handling uri: unknown
Traceback (most recent call last):
  File "/home/abwao/.local/lib/python3.6/site-packages/sanic/server.py", line 267, in data_received
    self.parser.feed_data(data)
  File "httptools/parser/parser.pyx", line 193, in httptools.parser.parser.HttpParser.feed_data
httptools.parser.errors.HttpParserInvalidMethodError: invalid HTTP method
2019-07-22 21:26:45,045 [ERROR]  Exception occurred while handling uri: unknown
Traceback (most recent call last):
  File "/home/abwao/.local/lib/python3.6/site-packages/sanic/server.py", line 267, in data_received
    self.parser.feed_data(data)
  File "httptools/parser/parser.pyx", line 193, in httptools.parser.parser.HttpParser.feed_data
httptools.parser.errors.HttpParserInvalidMethodError: invalid HTTP method
2019-07-22 21:26:51,043 [ERROR]  Exception occurred while handling uri: unknown
Traceback (most recent call last):
  File "/home/abwao/.local/lib/python3.6/site-packages/sanic/server.py", line 267, in data_received
    self.parser.feed_data(data)
  File "httptools/parser/parser.pyx", line 193, in httptools.parser.parser.HttpParser.feed_data
httptools.parser.errors.HttpParserInvalidMethodError: invalid HTTP method
2019-07-22 21:26:51,045 [ERROR]  Exception occurred while handling uri: unknown
Traceback (most recent call last):
  File "/home/abwao/.local/lib/python3.6/site-packages/sanic/server.py", line 267, in data_received
    self.parser.feed_data(data)
  File "httptools/parser/parser.pyx", line 193, in httptools.parser.parser.HttpParser.feed_data
httptools.parser.errors.HttpParserInvalidMethodError: invalid HTTP method
2019-07-22 21:26:57,044 [ERROR]  Exception occurred while handling uri: unknown
Traceback (most recent call last):
  File "/home/abwao/.local/lib/python3.6/site-packages/sanic/server.py", line 267, in data_received
    self.parser.feed_data(data)
  File "httptools/parser/parser.pyx", line 193, in httptools.parser.parser.HttpParser.feed_data
httptools.parser.errors.HttpParserInvalidMethodError: invalid HTTP method
2019-07-22 21:26:57,045 [ERROR]  Exception occurred while handling uri: unknown
Traceback (most recent call last):
  File "/home/abwao/.local/lib/python3.6/site-packages/sanic/server.py", line 267, in data_received
    self.parser.feed_data(data)
  File "httptools/parser/parser.pyx", line 193, in httptools.parser.parser.HttpParser.feed_data
httptools.parser.errors.HttpParserInvalidMethodError: invalid HTTP method
2019-07-22 21:27:03,044 [ERROR]  Exception occurred while handling uri: unknown
Traceback (most recent call last):
  File "/home/abwao/.local/lib/python3.6/site-packages/sanic/server.py", line 267, in data_received
    self.parser.feed_data(data)
  File "httptools/parser/parser.pyx", line 193, in httptools.parser.parser.HttpParser.feed_data
httptools.parser.errors.HttpParserInvalidMethodError: invalid HTTP method
2019-07-22 21:27:03,046 [ERROR]  Exception occurred while handling uri: unknown
Traceback (most recent call last):
  File "/home/abwao/.local/lib/python3.6/site-packages/sanic/server.py", line 267, in data_received
    self.parser.feed_data(data)
  File "httptools/parser/parser.pyx", line 193, in httptools.parser.parser.HttpParser.feed_data
httptools.parser.errors.HttpParserInvalidMethodError: invalid HTTP method
2019-07-22 21:27:09,044 [ERROR]  Exception occurred while handling uri: unknown
Traceback (most recent call last):
  File "/home/abwao/.local/lib/python3.6/site-packages/sanic/server.py", line 267, in data_received
    self.parser.feed_data(data)
  File "httptools/parser/parser.pyx", line 193, in httptools.parser.parser.HttpParser.feed_data
httptools.parser.errors.HttpParserInvalidMethodError: invalid HTTP method
2019-07-22 21:27:09,047 [ERROR]  Exception occurred while handling uri: unknown
Traceback (most recent call last):
  File "/home/abwao/.local/lib/python3.6/site-packages/sanic/server.py", line 267, in data_received
    self.parser.feed_data(data)
  File "httptools/parser/parser.pyx", line 193, in httptools.parser.parser.HttpParser.feed_data
httptools.parser.errors.HttpParserInvalidMethodError: invalid HTTP method
2019-07-22 21:31:06,629 [ERROR]  Exception occurred in one of response middleware handlers
Traceback (most recent call last):
  File "/home/abwao/.local/lib/python3.6/site-packages/sanic/app.py", line 958, in handle_request
    request, response
  File "/home/abwao/.local/lib/python3.6/site-packages/spf/framework.py", line 543, in _run_response_middleware
    _response = await _response
  File "/home/abwao/.local/lib/python3.6/site-packages/sanic_cors/extension.py", line 266, in unapplied_cors_response_middleware
    set_cors_headers(req, resp, context, res_options)
  File "/home/abwao/.local/lib/python3.6/site-packages/sanic_cors/core.py", line 248, in set_cors_headers
    if resp.headers is None:
AttributeError: 'list' object has no attribute 'headers'
2019-07-22 21:31:07,893 [ERROR]  Exception occurred in one of response middleware handlers
Traceback (most recent call last):
  File "/home/abwao/.local/lib/python3.6/site-packages/sanic/app.py", line 958, in handle_request
    request, response
  File "/home/abwao/.local/lib/python3.6/site-packages/spf/framework.py", line 543, in _run_response_middleware
    _response = await _response
  File "/home/abwao/.local/lib/python3.6/site-packages/sanic_cors/extension.py", line 266, in unapplied_cors_response_middleware
    set_cors_headers(req, resp, context, res_options)
  File "/home/abwao/.local/lib/python3.6/site-packages/sanic_cors/core.py", line 248, in set_cors_headers
    if resp.headers is None:
AttributeError: 'list' object has no attribute 'headers'
2019-07-22 22:25:03,920 [ERROR]  Exception occurred in one of response middleware handlers
Traceback (most recent call last):
  File "/home/abwao/.local/lib/python3.6/site-packages/sanic/app.py", line 958, in handle_request
    request, response
  File "/home/abwao/.local/lib/python3.6/site-packages/spf/framework.py", line 543, in _run_response_middleware
    _response = await _response
  File "/home/abwao/.local/lib/python3.6/site-packages/sanic_cors/extension.py", line 266, in unapplied_cors_response_middleware
    set_cors_headers(req, resp, context, res_options)
  File "/home/abwao/.local/lib/python3.6/site-packages/sanic_cors/core.py", line 248, in set_cors_headers
    if resp.headers is None:
AttributeError: 'list' object has no attribute 'headers'
2019-07-22 22:27:12,198 [ERROR]  Exception occurred in one of response middleware handlers
Traceback (most recent call last):
  File "/home/abwao/.local/lib/python3.6/site-packages/sanic/app.py", line 958, in handle_request
    request, response
  File "/home/abwao/.local/lib/python3.6/site-packages/spf/framework.py", line 543, in _run_response_middleware
    _response = await _response
  File "/home/abwao/.local/lib/python3.6/site-packages/sanic_cors/extension.py", line 266, in unapplied_cors_response_middleware
    set_cors_headers(req, resp, context, res_options)
  File "/home/abwao/.local/lib/python3.6/site-packages/sanic_cors/core.py", line 248, in set_cors_headers
    if resp.headers is None:
AttributeError: 'list' object has no attribute 'headers'
2019-07-23 13:00:39,018 [ERROR]  Exception occurred in one of response middleware handlers
Traceback (most recent call last):
  File "/home/abwao/.local/lib/python3.6/site-packages/sanic/app.py", line 958, in handle_request
    request, response
  File "/home/abwao/.local/lib/python3.6/site-packages/spf/framework.py", line 543, in _run_response_middleware
    _response = await _response
  File "/home/abwao/.local/lib/python3.6/site-packages/sanic_cors/extension.py", line 266, in unapplied_cors_response_middleware
    set_cors_headers(req, resp, context, res_options)
  File "/home/abwao/.local/lib/python3.6/site-packages/sanic_cors/core.py", line 248, in set_cors_headers
    if resp.headers is None:
AttributeError: 'list' object has no attribute 'headers'
2019-07-23 13:07:14,424 [ERROR]  Exception occurred in one of response middleware handlers
Traceback (most recent call last):
  File "/home/abwao/.local/lib/python3.6/site-packages/sanic/app.py", line 958, in handle_request
    request, response
  File "/home/abwao/.local/lib/python3.6/site-packages/spf/framework.py", line 543, in _run_response_middleware
    _response = await _response
  File "/home/abwao/.local/lib/python3.6/site-packages/sanic_cors/extension.py", line 266, in unapplied_cors_response_middleware
    set_cors_headers(req, resp, context, res_options)
  File "/home/abwao/.local/lib/python3.6/site-packages/sanic_cors/core.py", line 248, in set_cors_headers
    if resp.headers is None:
AttributeError: 'list' object has no attribute 'headers'
2019-07-23 13:07:16,990 [ERROR]  Exception occurred in one of response middleware handlers
Traceback (most recent call last):
  File "/home/abwao/.local/lib/python3.6/site-packages/sanic/app.py", line 958, in handle_request
    request, response
  File "/home/abwao/.local/lib/python3.6/site-packages/spf/framework.py", line 543, in _run_response_middleware
    _response = await _response
  File "/home/abwao/.local/lib/python3.6/site-packages/sanic_cors/extension.py", line 266, in unapplied_cors_response_middleware
    set_cors_headers(req, resp, context, res_options)
  File "/home/abwao/.local/lib/python3.6/site-packages/sanic_cors/core.py", line 248, in set_cors_headers
    if resp.headers is None:
AttributeError: 'list' object has no attribute 'headers'
2019-07-23 13:07:29,896 [ERROR]  Exception occurred in one of response middleware handlers
Traceback (most recent call last):
  File "/home/abwao/.local/lib/python3.6/site-packages/sanic/app.py", line 958, in handle_request
    request, response
  File "/home/abwao/.local/lib/python3.6/site-packages/spf/framework.py", line 543, in _run_response_middleware
    _response = await _response
  File "/home/abwao/.local/lib/python3.6/site-packages/sanic_cors/extension.py", line 266, in unapplied_cors_response_middleware
    set_cors_headers(req, resp, context, res_options)
  File "/home/abwao/.local/lib/python3.6/site-packages/sanic_cors/core.py", line 248, in set_cors_headers
    if resp.headers is None:
AttributeError: 'list' object has no attribute 'headers'
2019-07-23 14:32:19,783 [ERROR]  Exception occurred in one of response middleware handlers
Traceback (most recent call last):
  File "/home/abwao/.local/lib/python3.6/site-packages/sanic/app.py", line 958, in handle_request
    request, response
  File "/home/abwao/.local/lib/python3.6/site-packages/spf/framework.py", line 543, in _run_response_middleware
    _response = await _response
  File "/home/abwao/.local/lib/python3.6/site-packages/sanic_cors/extension.py", line 266, in unapplied_cors_response_middleware
    set_cors_headers(req, resp, context, res_options)
  File "/home/abwao/.local/lib/python3.6/site-packages/sanic_cors/core.py", line 248, in set_cors_headers
    if resp.headers is None:
AttributeError: 'list' object has no attribute 'headers'
2019-07-23 14:45:13,833 [ERROR]  Exception occurred in one of response middleware handlers
Traceback (most recent call last):
  File "/home/abwao/.local/lib/python3.6/site-packages/sanic/app.py", line 958, in handle_request
    request, response
  File "/home/abwao/.local/lib/python3.6/site-packages/spf/framework.py", line 543, in _run_response_middleware
    _response = await _response
  File "/home/abwao/.local/lib/python3.6/site-packages/sanic_cors/extension.py", line 266, in unapplied_cors_response_middleware
    set_cors_headers(req, resp, context, res_options)
  File "/home/abwao/.local/lib/python3.6/site-packages/sanic_cors/core.py", line 248, in set_cors_headers
    if resp.headers is None:
AttributeError: 'list' object has no attribute 'headers'
2019-07-23 15:16:07,934 [ERROR]  Exception occurred in one of response middleware handlers
Traceback (most recent call last):
  File "/home/abwao/.local/lib/python3.6/site-packages/sanic/app.py", line 958, in handle_request
    request, response
  File "/home/abwao/.local/lib/python3.6/site-packages/spf/framework.py", line 543, in _run_response_middleware
    _response = await _response
  File "/home/abwao/.local/lib/python3.6/site-packages/sanic_cors/extension.py", line 266, in unapplied_cors_response_middleware
    set_cors_headers(req, resp, context, res_options)
  File "/home/abwao/.local/lib/python3.6/site-packages/sanic_cors/core.py", line 248, in set_cors_headers
    if resp.headers is None:
AttributeError: 'list' object has no attribute 'headers'
2019-07-23 16:55:03,615 [ERROR]  Exception occurred in one of response middleware handlers
Traceback (most recent call last):
  File "/home/abwao/.local/lib/python3.6/site-packages/sanic/app.py", line 958, in handle_request
    request, response
  File "/home/abwao/.local/lib/python3.6/site-packages/spf/framework.py", line 543, in _run_response_middleware
    _response = await _response
  File "/home/abwao/.local/lib/python3.6/site-packages/sanic_cors/extension.py", line 266, in unapplied_cors_response_middleware
    set_cors_headers(req, resp, context, res_options)
  File "/home/abwao/.local/lib/python3.6/site-packages/sanic_cors/core.py", line 248, in set_cors_headers
    if resp.headers is None:
AttributeError: 'list' object has no attribute 'headers'
2019-07-23 17:06:34,307 [ERROR]  Exception occurred in one of response middleware handlers
Traceback (most recent call last):
  File "/home/abwao/.local/lib/python3.6/site-packages/sanic/app.py", line 958, in handle_request
    request, response
  File "/home/abwao/.local/lib/python3.6/site-packages/spf/framework.py", line 543, in _run_response_middleware
    _response = await _response
  File "/home/abwao/.local/lib/python3.6/site-packages/sanic_cors/extension.py", line 266, in unapplied_cors_response_middleware
    set_cors_headers(req, resp, context, res_options)
  File "/home/abwao/.local/lib/python3.6/site-packages/sanic_cors/core.py", line 248, in set_cors_headers
    if resp.headers is None:
AttributeError: 'list' object has no attribute 'headers'
2019-07-23 17:08:16,380 [ERROR]  Exception occurred in one of response middleware handlers
Traceback (most recent call last):
  File "/home/abwao/.local/lib/python3.6/site-packages/sanic/app.py", line 958, in handle_request
    request, response
  File "/home/abwao/.local/lib/python3.6/site-packages/spf/framework.py", line 543, in _run_response_middleware
    _response = await _response
  File "/home/abwao/.local/lib/python3.6/site-packages/sanic_cors/extension.py", line 266, in unapplied_cors_response_middleware
    set_cors_headers(req, resp, context, res_options)
  File "/home/abwao/.local/lib/python3.6/site-packages/sanic_cors/core.py", line 248, in set_cors_headers
    if resp.headers is None:
AttributeError: 'list' object has no attribute 'headers'
2019-07-23 17:37:09,455 [ERROR]  Exception occurred in one of response middleware handlers
Traceback (most recent call last):
  File "/home/abwao/.local/lib/python3.6/site-packages/sanic/app.py", line 958, in handle_request
    request, response
  File "/home/abwao/.local/lib/python3.6/site-packages/spf/framework.py", line 543, in _run_response_middleware
    _response = await _response
  File "/home/abwao/.local/lib/python3.6/site-packages/sanic_cors/extension.py", line 266, in unapplied_cors_response_middleware
    set_cors_headers(req, resp, context, res_options)
  File "/home/abwao/.local/lib/python3.6/site-packages/sanic_cors/core.py", line 248, in set_cors_headers
    if resp.headers is None:
AttributeError: 'list' object has no attribute 'headers'
